2025-07-09 00:22:32,918 INFO    StreamThr :33052 [internal.py:wandb_internal():86] W&B internal server running at pid: 33052, started at: 2025-07-09 00:22:32.917040
2025-07-09 00:22:32,920 DEBUG   HandlerThread:33052 [handler.py:handle_request():144] handle_request: status
2025-07-09 00:22:32,922 INFO    WriterThread:33052 [datastore.py:open_for_write():85] open: /home/ubuntu/universal_manipulation_interface/wandb/run-20250709_002232-fcacadrt/run-fcacadrt.wandb
2025-07-09 00:22:32,923 DEBUG   SenderThread:33052 [sender.py:send():379] send: header
2025-07-09 00:22:32,974 DEBUG   SenderThread:33052 [sender.py:send():379] send: run
2025-07-09 00:22:37,976 DEBUG   HandlerThread:33052 [handler.py:handle_request():144] handle_request: keepalive
2025-07-09 00:22:42,978 DEBUG   HandlerThread:33052 [handler.py:handle_request():144] handle_request: keepalive
2025-07-09 00:22:47,980 DEBUG   HandlerThread:33052 [handler.py:handle_request():144] handle_request: keepalive
2025-07-09 00:22:52,982 DEBUG   HandlerThread:33052 [handler.py:handle_request():144] handle_request: keepalive
2025-07-09 00:22:57,984 DEBUG   HandlerThread:33052 [handler.py:handle_request():144] handle_request: keepalive
2025-07-09 00:23:02,986 DEBUG   HandlerThread:33052 [handler.py:handle_request():144] handle_request: keepalive
2025-07-09 00:23:07,081 INFO    SenderThread:33052 [retry.py:__call__():172] Retry attempt failed:
Traceback (most recent call last):
  File "/home/ubuntu/miniforge3/envs/umi/lib/python3.9/site-packages/urllib3/connection.py", line 174, in _new_conn
    conn = connection.create_connection(
  File "/home/ubuntu/miniforge3/envs/umi/lib/python3.9/site-packages/urllib3/util/connection.py", line 95, in create_connection
    raise err
  File "/home/ubuntu/miniforge3/envs/umi/lib/python3.9/site-packages/urllib3/util/connection.py", line 85, in create_connection
    sock.connect(sa)
socket.timeout: timed out

During handling of the above exception, another exception occurred:

Traceback (most recent call last):
  File "/home/ubuntu/miniforge3/envs/umi/lib/python3.9/site-packages/urllib3/connectionpool.py", line 715, in urlopen
    httplib_response = self._make_request(
  File "/home/ubuntu/miniforge3/envs/umi/lib/python3.9/site-packages/urllib3/connectionpool.py", line 404, in _make_request
    self._validate_conn(conn)
  File "/home/ubuntu/miniforge3/envs/umi/lib/python3.9/site-packages/urllib3/connectionpool.py", line 1060, in _validate_conn
    conn.connect()
  File "/home/ubuntu/miniforge3/envs/umi/lib/python3.9/site-packages/urllib3/connection.py", line 363, in connect
    self.sock = conn = self._new_conn()
  File "/home/ubuntu/miniforge3/envs/umi/lib/python3.9/site-packages/urllib3/connection.py", line 179, in _new_conn
    raise ConnectTimeoutError(
urllib3.exceptions.ConnectTimeoutError: (<urllib3.connection.HTTPSConnection object at 0x7f49e849f250>, 'Connection to api.wandb.ai timed out. (connect timeout=10)')

During handling of the above exception, another exception occurred:

Traceback (most recent call last):
  File "/home/ubuntu/miniforge3/envs/umi/lib/python3.9/site-packages/requests/adapters.py", line 667, in send
    resp = conn.urlopen(
  File "/home/ubuntu/miniforge3/envs/umi/lib/python3.9/site-packages/urllib3/connectionpool.py", line 801, in urlopen
    retries = retries.increment(
  File "/home/ubuntu/miniforge3/envs/umi/lib/python3.9/site-packages/urllib3/util/retry.py", line 594, in increment
    raise MaxRetryError(_pool, url, error or ResponseError(cause))
urllib3.exceptions.MaxRetryError: HTTPSConnectionPool(host='api.wandb.ai', port=443): Max retries exceeded with url: /graphql (Caused by ConnectTimeoutError(<urllib3.connection.HTTPSConnection object at 0x7f49e849f250>, 'Connection to api.wandb.ai timed out. (connect timeout=10)'))

During handling of the above exception, another exception occurred:

Traceback (most recent call last):
  File "/home/ubuntu/miniforge3/envs/umi/lib/python3.9/site-packages/wandb/sdk/lib/retry.py", line 131, in __call__
    result = self._call_fn(*args, **kwargs)
  File "/home/ubuntu/miniforge3/envs/umi/lib/python3.9/site-packages/wandb/sdk/internal/internal_api.py", line 323, in execute
    return self.client.execute(*args, **kwargs)  # type: ignore
  File "/home/ubuntu/miniforge3/envs/umi/lib/python3.9/site-packages/wandb/vendor/gql-0.2.0/wandb_gql/client.py", line 52, in execute
    result = self._get_result(document, *args, **kwargs)
  File "/home/ubuntu/miniforge3/envs/umi/lib/python3.9/site-packages/wandb/vendor/gql-0.2.0/wandb_gql/client.py", line 60, in _get_result
    return self.transport.execute(document, *args, **kwargs)
  File "/home/ubuntu/miniforge3/envs/umi/lib/python3.9/site-packages/wandb/sdk/lib/gql_request.py", line 55, in execute
    request = self.session.post(self.url, **post_args)
  File "/home/ubuntu/miniforge3/envs/umi/lib/python3.9/site-packages/requests/sessions.py", line 637, in post
    return self.request("POST", url, data=data, json=json, **kwargs)
  File "/home/ubuntu/miniforge3/envs/umi/lib/python3.9/site-packages/requests/sessions.py", line 589, in request
    resp = self.send(prep, **send_kwargs)
  File "/home/ubuntu/miniforge3/envs/umi/lib/python3.9/site-packages/requests/sessions.py", line 703, in send
    r = adapter.send(request, **kwargs)
  File "/home/ubuntu/miniforge3/envs/umi/lib/python3.9/site-packages/requests/adapters.py", line 688, in send
    raise ConnectTimeout(e, request=request)
requests.exceptions.ConnectTimeout: HTTPSConnectionPool(host='api.wandb.ai', port=443): Max retries exceeded with url: /graphql (Caused by ConnectTimeoutError(<urllib3.connection.HTTPSConnection object at 0x7f49e849f250>, 'Connection to api.wandb.ai timed out. (connect timeout=10)'))
2025-07-09 00:23:07,988 DEBUG   HandlerThread:33052 [handler.py:handle_request():144] handle_request: keepalive
2025-07-09 00:23:12,990 DEBUG   HandlerThread:33052 [handler.py:handle_request():144] handle_request: keepalive
2025-07-09 00:23:17,992 DEBUG   HandlerThread:33052 [handler.py:handle_request():144] handle_request: keepalive
2025-07-09 00:23:22,994 DEBUG   HandlerThread:33052 [handler.py:handle_request():144] handle_request: keepalive
2025-07-09 00:23:27,996 DEBUG   HandlerThread:33052 [handler.py:handle_request():144] handle_request: keepalive
2025-07-09 00:23:33,001 DEBUG   HandlerThread:33052 [handler.py:handle_request():144] handle_request: cancel
2025-07-09 00:23:33,001 DEBUG   HandlerThread:33052 [handler.py:handle_request():144] handle_request: cancel
2025-07-09 00:23:33,962 DEBUG   HandlerThread:33052 [handler.py:handle_request():144] handle_request: shutdown
2025-07-09 00:23:33,962 INFO    HandlerThread:33052 [handler.py:finish():857] shutting down handler
2025-07-09 00:23:34,001 INFO    WriterThread:33052 [datastore.py:close():294] close: /home/ubuntu/universal_manipulation_interface/wandb/run-20250709_002232-fcacadrt/run-fcacadrt.wandb
2025-07-09 00:23:41,545 DEBUG   SenderThread:33052 [sender.py:send():388] Record cancelled: run
2025-07-09 00:23:41,545 INFO    SenderThread:33052 [sender.py:finish():1552] shutting down sender
